\mode*

\section{Fel och felhantering}

\subsection{Särfall}

\begin{frame}[fragile]
  \begin{example}
    \begin{minted}{text}
>>> int("a")
Traceback (most recent call last):
  File "<stdin>", line 1, in <module>
ValueError: invalid literal for int() with base 10: 'a'
>>> 
    \end{minted}
  \end{example}
\end{frame}

\begin{frame}[fragile]
  \begin{example}
    \begin{minted}{text}
>>> 5/0
Traceback (most recent call last):
  File "<stdin>", line 1, in <module>
ZeroDivisionError: division by zero
>>> 
    \end{minted}
  \end{example}
\end{frame}

\begin{frame}[fragile]
  \begin{example}
    \begin{minted}{text}
>>> prynt(3)
Traceback (most recent call last):
  File "<stdin>", line 1, in <module>
NameError: name 'prynt' is not defined
>>> 
    \end{minted}
  \end{example}
\end{frame}

\subsection{Felhantering: att fånga särfall}

\begin{frame}
  \includegraphics[width=\columnwidth]{figs/docs-except.png}
\end{frame}

\begin{frame}[fragile]
  \begin{example}[Fånga särfall: valuerr.py]
    \inputminted{python}{examples/valuerr.py}
  \end{example}

  \pause

  \begin{example}
    \begin{minted}{text}
$ python3 valuerr.py
We caught this: invalid literal for int() with base 10: 'a'
    \end{minted}
  \end{example}
\end{frame}

\begin{frame}[fragile]
  \begin{minted}{python}
try:
  # error
except Exception as err:
  print("Catch all errors!")
  \end{minted}
  \begin{remark}
    \begin{itemize}
      \item \mint{python}{except Exception as err} fångar \emph{allt}!
    \end{itemize}
  \end{remark}
\end{frame}

\begin{frame}[fragile]
  \begin{example}[manyerr.py]
    \inputminted{python}{examples/manyerr.py}
  \end{example}
\end{frame}

